<?xml version="1.0" ?>
<!-- =================================================================================== -->
<!-- |    This document was autogenerated by xacro from hexapod2022c.xacro             | -->
<!-- |    EDITING THIS FILE BY HAND IS NOT RECOMMENDED                                 | -->
<!-- =================================================================================== -->
<robot name="Hexapod2022">
  <material name="white">
    <color rgba="1 1 1 1"/>
  </material>
  <material name="red">
    <color rgba="1 0 0 1"/>
  </material>
  <!-- main body -->
  <link name="base_link"/>
  <link name="body_link">
    <visual>
      <geometry>
        <mesh filename="package://hexapod_urdf/meshes/hexapod_body.stl" scale="0.001 0.001 0.001"/>
      </geometry>
      <material name="white"/>
    </visual>
    <collision>
      <geometry>
        <box size="0.27 0.09 0.138"/>
      </geometry>
      <origin rpy="0 0 0" xyz="0 0 0.04875"/>
    </collision>
    <inertial>
      <origin rpy="0 0 0" xyz="0 0 0.04875"/>
      <mass value="1.060"/>
      <inertia ixx="0.00239772" ixy="0" ixz="0" iyy="0.00812172" iyz="0" izz="0.007155"/>
    </inertial>
  </link>
  <joint name="base_joint" type="fixed">
    <parent link="base_link"/>
    <child link="body_link"/>
  </joint>
  <!-- <link name="base_stabilized"/>
    <joint name="base_orientation_joint" type="fixed">
        <parent link="base_stabilized" />
        <child link="base_link" />
    </joint> -->
  <!-- leg base -->
  <link name="right_rear_leg_base">
    <inertial>
      <origin rpy="0 0 0" xyz="0 0 0"/>
      <mass value="0.006"/>
      <inertia ixx="0.0000001" ixy="0" ixz="0" iyy="0.0000001" iyz="0" izz="0.0000001"/>
    </inertial>
  </link>
  <joint name="right_rear_leg_base_joint" type="fixed">
    <origin rpy="0.0 0.0 0.0" xyz="-0.065 -0.0325 0.0"/>
    <parent link="body_link"/>
    <child link="right_rear_leg_base"/>
  </joint>
  <!-- coxa -->
  <link name="right_rear_coxa">
    <visual>
      <geometry>
        <mesh filename="package://hexapod_urdf/meshes/hopper_leg_coxa.stl" scale="0.001 0.001 0.001"/>
      </geometry>
      <material name="white"/>
    </visual>
    <inertial>
      <origin rpy="0 0 0" xyz="0 0 0"/>
      <mass value="0.006"/>
      <inertia ixx="0.0000001" ixy="0" ixz="0" iyy="0.0000001" iyz="0" izz="0.0000001"/>
    </inertial>
  </link>
  <joint name="right_rear_coxa_joint" type="revolute">
    <origin rpy="0.0 0.0 -1.5707963267948966" xyz="0.0 0.0 0.0"/>
    <parent link="right_rear_leg_base"/>
    <child link="right_rear_coxa"/>
    <axis xyz="0.0 0.0 1.0"/>
    <limit effort="1000.0" lower="-3.141592653589793" upper="3.141592653589793" velocity="1"/>
  </joint>
  <!-- femur -->
  <link name="right_rear_femur">
    <visual>
      <geometry>
        <mesh filename="package://hexapod_urdf/meshes/hopper_leg_femur.stl" scale="0.001 0.001 0.001"/>
      </geometry>
      <material name="white"/>
    </visual>
    <collision>
      <geometry>
        <box size="0.038 0.05 0.032"/>
      </geometry>
      <origin rpy="0 0 0.06981317007977318" xyz="0.00094 -0.01346 0"/>
    </collision>
    <inertial>
      <origin rpy="0 0 0.06981317007977318" xyz="0.00094 -0.01346 0"/>
      <mass value="0.091"/>
      <inertia ixx="0.00002672366667" ixy="0" ixz="0" iyy="0.00001989866667" iyz="0" izz="0.00003109166667"/>
    </inertial>
  </link>
  <joint name="right_rear_femur_joint" type="revolute">
    <origin rpy="-1.5707963267948966 1.5707963267948966 0.0" xyz="0.044 0.0 0.0"/>
    <parent link="right_rear_coxa"/>
    <child link="right_rear_femur"/>
    <axis xyz="0.0 0.0 -1"/>
    <limit effort="1000.0" lower="-3.141592653589793" upper="3.141592653589793" velocity="1"/>
  </joint>
  <!-- tibia -->
  <link name="right_rear_tibia">
    <visual>
      <geometry>
        <mesh filename="package://hexapod_urdf/meshes/hopper_leg_tibia.stl" scale="0.001 0.001 0.001"/>
      </geometry>
      <material name="white"/>
    </visual>
    <collision>
      <geometry>
        <box size="0.124 0.019 0.04"/>
      </geometry>
      <origin rpy="0 0 -0.29671256645162386" xyz="0.0535 0.023 0"/>
    </collision>
    <inertial>
      <origin rpy="0 0 -0.29671256645162386" xyz="0.0535 0.023 0"/>
      <mass value="0.091"/>
      <inertia ixx="0.0000148709166667" ixy="0" ixz="0" iyy="0.00016938133333" iyz="0" izz="0.0001599855833333"/>
    </inertial>
  </link>
  <joint name="right_rear_tibia_joint" type="revolute">
    <origin rpy="3.141592653589793 0.0 0.0" xyz="0.0 -0.07 0.0"/>
    <parent link="right_rear_femur"/>
    <child link="right_rear_tibia"/>
    <axis xyz="0.0 0.0 1"/>
    <limit effort="1000.0" lower="-3.141592653589793" upper="3.141592653589793" velocity="1"/>
  </joint>
  <link name="right_rear_button">
    <inertial>
      <origin rpy="0 0 0" xyz="0 0 0"/>
      <mass value="0.006"/>
      <inertia ixx="0.0000001" ixy="0" ixz="0" iyy="0.0000001" iyz="0" izz="0.0000001"/>
    </inertial>
  </link>
  <joint name="right_rear_tibia_button" type="fixed">
    <origin xyz="0.128 0.0 0.0"/>
    <parent link="right_rear_tibia"/>
    <child link="right_rear_button"/>
  </joint>
  <!-- leg base -->
  <link name="right_middle_leg_base">
    <inertial>
      <origin rpy="0 0 0" xyz="0 0 0"/>
      <mass value="0.006"/>
      <inertia ixx="0.0000001" ixy="0" ixz="0" iyy="0.0000001" iyz="0" izz="0.0000001"/>
    </inertial>
  </link>
  <joint name="right_middle_leg_base_joint" type="fixed">
    <origin rpy="0.0 0.0 0.0" xyz="0.0 -0.0625 0.0"/>
    <parent link="body_link"/>
    <child link="right_middle_leg_base"/>
  </joint>
  <!-- coxa -->
  <link name="right_middle_coxa">
    <visual>
      <geometry>
        <mesh filename="package://hexapod_urdf/meshes/hopper_leg_coxa.stl" scale="0.001 0.001 0.001"/>
      </geometry>
      <material name="white"/>
    </visual>
    <inertial>
      <origin rpy="0 0 0" xyz="0 0 0"/>
      <mass value="0.006"/>
      <inertia ixx="0.0000001" ixy="0" ixz="0" iyy="0.0000001" iyz="0" izz="0.0000001"/>
    </inertial>
  </link>
  <joint name="right_middle_coxa_joint" type="revolute">
    <origin rpy="0.0 0.0 -1.5707963267948966" xyz="0.0 0.0 0.0"/>
    <parent link="right_middle_leg_base"/>
    <child link="right_middle_coxa"/>
    <axis xyz="0.0 0.0 1.0"/>
    <limit effort="1000.0" lower="-3.141592653589793" upper="3.141592653589793" velocity="1"/>
  </joint>
  <!-- femur -->
  <link name="right_middle_femur">
    <visual>
      <geometry>
        <mesh filename="package://hexapod_urdf/meshes/hopper_leg_femur.stl" scale="0.001 0.001 0.001"/>
      </geometry>
      <material name="white"/>
    </visual>
    <collision>
      <geometry>
        <box size="0.038 0.05 0.032"/>
      </geometry>
      <origin rpy="0 0 0.06981317007977318" xyz="0.00094 -0.01346 0"/>
    </collision>
    <inertial>
      <origin rpy="0 0 0.06981317007977318" xyz="0.00094 -0.01346 0"/>
      <mass value="0.091"/>
      <inertia ixx="0.00002672366667" ixy="0" ixz="0" iyy="0.00001989866667" iyz="0" izz="0.00003109166667"/>
    </inertial>
  </link>
  <joint name="right_middle_femur_joint" type="revolute">
    <origin rpy="-1.5707963267948966 1.5707963267948966 0.0" xyz="0.044 0.0 0.0"/>
    <parent link="right_middle_coxa"/>
    <child link="right_middle_femur"/>
    <axis xyz="0.0 0.0 -1"/>
    <limit effort="1000.0" lower="-3.141592653589793" upper="3.141592653589793" velocity="1"/>
  </joint>
  <!-- tibia -->
  <link name="right_middle_tibia">
    <visual>
      <geometry>
        <mesh filename="package://hexapod_urdf/meshes/hopper_leg_tibia.stl" scale="0.001 0.001 0.001"/>
      </geometry>
      <material name="white"/>
    </visual>
    <collision>
      <geometry>
        <box size="0.124 0.019 0.04"/>
      </geometry>
      <origin rpy="0 0 -0.29671256645162386" xyz="0.0535 0.023 0"/>
    </collision>
    <inertial>
      <origin rpy="0 0 -0.29671256645162386" xyz="0.0535 0.023 0"/>
      <mass value="0.091"/>
      <inertia ixx="0.0000148709166667" ixy="0" ixz="0" iyy="0.00016938133333" iyz="0" izz="0.0001599855833333"/>
    </inertial>
  </link>
  <joint name="right_middle_tibia_joint" type="revolute">
    <origin rpy="3.141592653589793 0.0 0.0" xyz="0.0 -0.07 0.0"/>
    <parent link="right_middle_femur"/>
    <child link="right_middle_tibia"/>
    <axis xyz="0.0 0.0 1"/>
    <limit effort="1000.0" lower="-3.141592653589793" upper="3.141592653589793" velocity="1"/>
  </joint>
  <link name="right_middle_button">
    <inertial>
      <origin rpy="0 0 0" xyz="0 0 0"/>
      <mass value="0.006"/>
      <inertia ixx="0.0000001" ixy="0" ixz="0" iyy="0.0000001" iyz="0" izz="0.0000001"/>
    </inertial>
  </link>
  <joint name="right_middle_tibia_button" type="fixed">
    <origin xyz="0.128 0.0 0.0"/>
    <parent link="right_middle_tibia"/>
    <child link="right_middle_button"/>
  </joint>
  <!-- leg base -->
  <link name="right_front_leg_base">
    <inertial>
      <origin rpy="0 0 0" xyz="0 0 0"/>
      <mass value="0.006"/>
      <inertia ixx="0.0000001" ixy="0" ixz="0" iyy="0.0000001" iyz="0" izz="0.0000001"/>
    </inertial>
  </link>
  <joint name="right_front_leg_base_joint" type="fixed">
    <origin rpy="0.0 0.0 0.0" xyz="0.065 -0.0325 0.0"/>
    <parent link="body_link"/>
    <child link="right_front_leg_base"/>
  </joint>
  <!-- coxa -->
  <link name="right_front_coxa">
    <visual>
      <geometry>
        <mesh filename="package://hexapod_urdf/meshes/hopper_leg_coxa.stl" scale="0.001 0.001 0.001"/>
      </geometry>
      <material name="white"/>
    </visual>
    <inertial>
      <origin rpy="0 0 0" xyz="0 0 0"/>
      <mass value="0.006"/>
      <inertia ixx="0.0000001" ixy="0" ixz="0" iyy="0.0000001" iyz="0" izz="0.0000001"/>
    </inertial>
  </link>
  <joint name="right_front_coxa_joint" type="revolute">
    <origin rpy="0.0 0.0 -1.5707963267948966" xyz="0.0 0.0 0.0"/>
    <parent link="right_front_leg_base"/>
    <child link="right_front_coxa"/>
    <axis xyz="0.0 0.0 1.0"/>
    <limit effort="1000.0" lower="-3.141592653589793" upper="3.141592653589793" velocity="1"/>
  </joint>
  <!-- femur -->
  <link name="right_front_femur">
    <visual>
      <geometry>
        <mesh filename="package://hexapod_urdf/meshes/hopper_leg_femur.stl" scale="0.001 0.001 0.001"/>
      </geometry>
      <material name="white"/>
    </visual>
    <collision>
      <geometry>
        <box size="0.038 0.05 0.032"/>
      </geometry>
      <origin rpy="0 0 0.06981317007977318" xyz="0.00094 -0.01346 0"/>
    </collision>
    <inertial>
      <origin rpy="0 0 0.06981317007977318" xyz="0.00094 -0.01346 0"/>
      <mass value="0.091"/>
      <inertia ixx="0.00002672366667" ixy="0" ixz="0" iyy="0.00001989866667" iyz="0" izz="0.00003109166667"/>
    </inertial>
  </link>
  <joint name="right_front_femur_joint" type="revolute">
    <origin rpy="-1.5707963267948966 1.5707963267948966 0.0" xyz="0.044 0.0 0.0"/>
    <parent link="right_front_coxa"/>
    <child link="right_front_femur"/>
    <axis xyz="0.0 0.0 -1"/>
    <limit effort="1000.0" lower="-3.141592653589793" upper="3.141592653589793" velocity="1"/>
  </joint>
  <!-- tibia -->
  <link name="right_front_tibia">
    <visual>
      <geometry>
        <mesh filename="package://hexapod_urdf/meshes/hopper_leg_tibia.stl" scale="0.001 0.001 0.001"/>
      </geometry>
      <material name="white"/>
    </visual>
    <collision>
      <geometry>
        <box size="0.124 0.019 0.04"/>
      </geometry>
      <origin rpy="0 0 -0.29671256645162386" xyz="0.0535 0.023 0"/>
    </collision>
    <inertial>
      <origin rpy="0 0 -0.29671256645162386" xyz="0.0535 0.023 0"/>
      <mass value="0.091"/>
      <inertia ixx="0.0000148709166667" ixy="0" ixz="0" iyy="0.00016938133333" iyz="0" izz="0.0001599855833333"/>
    </inertial>
  </link>
  <joint name="right_front_tibia_joint" type="revolute">
    <origin rpy="3.141592653589793 0.0 0.0" xyz="0.0 -0.07 0.0"/>
    <parent link="right_front_femur"/>
    <child link="right_front_tibia"/>
    <axis xyz="0.0 0.0 1"/>
    <limit effort="1000.0" lower="-3.141592653589793" upper="3.141592653589793" velocity="1"/>
  </joint>
  <link name="right_front_button">
    <inertial>
      <origin rpy="0 0 0" xyz="0 0 0"/>
      <mass value="0.006"/>
      <inertia ixx="0.0000001" ixy="0" ixz="0" iyy="0.0000001" iyz="0" izz="0.0000001"/>
    </inertial>
  </link>
  <joint name="right_front_tibia_button" type="fixed">
    <origin xyz="0.128 0.0 0.0"/>
    <parent link="right_front_tibia"/>
    <child link="right_front_button"/>
  </joint>
  <!-- leg base -->
  <link name="left_rear_leg_base">
    <inertial>
      <origin rpy="0 0 0" xyz="0 0 0"/>
      <mass value="0.006"/>
      <inertia ixx="0.0000001" ixy="0" ixz="0" iyy="0.0000001" iyz="0" izz="0.0000001"/>
    </inertial>
  </link>
  <joint name="left_rear_leg_base_joint" type="fixed">
    <origin rpy="0.0 0.0 0.0" xyz="-0.065 0.0325 0.0"/>
    <parent link="body_link"/>
    <child link="left_rear_leg_base"/>
  </joint>
  <!-- coxa -->
  <link name="left_rear_coxa">
    <visual>
      <geometry>
        <mesh filename="package://hexapod_urdf/meshes/hopper_leg_coxa.stl" scale="0.001 0.001 0.001"/>
      </geometry>
      <material name="white"/>
    </visual>
    <inertial>
      <origin rpy="0 0 0" xyz="0 0 0"/>
      <mass value="0.006"/>
      <inertia ixx="0.0000001" ixy="0" ixz="0" iyy="0.0000001" iyz="0" izz="0.0000001"/>
    </inertial>
  </link>
  <joint name="left_rear_coxa_joint" type="revolute">
    <origin rpy="0.0 0.0 1.5707963267948966" xyz="0.0 0.0 0.0"/>
    <parent link="left_rear_leg_base"/>
    <child link="left_rear_coxa"/>
    <axis xyz="0.0 0.0 1.0"/>
    <limit effort="1000.0" lower="-3.141592653589793" upper="3.141592653589793" velocity="1"/>
  </joint>
  <!-- femur -->
  <link name="left_rear_femur">
    <visual>
      <geometry>
        <mesh filename="package://hexapod_urdf/meshes/hopper_leg_femur.stl" scale="0.001 0.001 0.001"/>
      </geometry>
      <material name="white"/>
    </visual>
    <collision>
      <geometry>
        <box size="0.038 0.05 0.032"/>
      </geometry>
      <origin rpy="0 0 0.06981317007977318" xyz="0.00094 -0.01346 0"/>
    </collision>
    <inertial>
      <origin rpy="0 0 0.06981317007977318" xyz="0.00094 -0.01346 0"/>
      <mass value="0.091"/>
      <inertia ixx="0.00002672366667" ixy="0" ixz="0" iyy="0.00001989866667" iyz="0" izz="0.00003109166667"/>
    </inertial>
  </link>
  <joint name="left_rear_femur_joint" type="revolute">
    <origin rpy="-1.5707963267948966 1.5707963267948966 0.0" xyz="0.044 0.0 0.0"/>
    <parent link="left_rear_coxa"/>
    <child link="left_rear_femur"/>
    <axis xyz="0.0 0.0 1"/>
    <limit effort="1000.0" lower="-3.141592653589793" upper="3.141592653589793" velocity="1"/>
  </joint>
  <!-- tibia -->
  <link name="left_rear_tibia">
    <visual>
      <geometry>
        <mesh filename="package://hexapod_urdf/meshes/hopper_leg_tibia.stl" scale="0.001 0.001 0.001"/>
      </geometry>
      <material name="white"/>
    </visual>
    <collision>
      <geometry>
        <box size="0.124 0.019 0.04"/>
      </geometry>
      <origin rpy="0 0 -0.29671256645162386" xyz="0.0535 0.023 0"/>
    </collision>
    <inertial>
      <origin rpy="0 0 -0.29671256645162386" xyz="0.0535 0.023 0"/>
      <mass value="0.091"/>
      <inertia ixx="0.0000148709166667" ixy="0" ixz="0" iyy="0.00016938133333" iyz="0" izz="0.0001599855833333"/>
    </inertial>
  </link>
  <joint name="left_rear_tibia_joint" type="revolute">
    <origin rpy="3.141592653589793 0.0 0.0" xyz="0.0 -0.07 0.0"/>
    <parent link="left_rear_femur"/>
    <child link="left_rear_tibia"/>
    <axis xyz="0.0 0.0 -1"/>
    <limit effort="1000.0" lower="-3.141592653589793" upper="3.141592653589793" velocity="1"/>
  </joint>
  <link name="left_rear_button">
    <inertial>
      <origin rpy="0 0 0" xyz="0 0 0"/>
      <mass value="0.006"/>
      <inertia ixx="0.0000001" ixy="0" ixz="0" iyy="0.0000001" iyz="0" izz="0.0000001"/>
    </inertial>
  </link>
  <joint name="left_rear_tibia_button" type="fixed">
    <origin xyz="0.128 0.0 0.0"/>
    <parent link="left_rear_tibia"/>
    <child link="left_rear_button"/>
  </joint>
  <!-- leg base -->
  <link name="left_middle_leg_base">
    <inertial>
      <origin rpy="0 0 0" xyz="0 0 0"/>
      <mass value="0.006"/>
      <inertia ixx="0.0000001" ixy="0" ixz="0" iyy="0.0000001" iyz="0" izz="0.0000001"/>
    </inertial>
  </link>
  <joint name="left_middle_leg_base_joint" type="fixed">
    <origin rpy="0.0 0.0 0.0" xyz="0.0 0.0625 0.0"/>
    <parent link="body_link"/>
    <child link="left_middle_leg_base"/>
  </joint>
  <!-- coxa -->
  <link name="left_middle_coxa">
    <visual>
      <geometry>
        <mesh filename="package://hexapod_urdf/meshes/hopper_leg_coxa.stl" scale="0.001 0.001 0.001"/>
      </geometry>
      <material name="white"/>
    </visual>
    <inertial>
      <origin rpy="0 0 0" xyz="0 0 0"/>
      <mass value="0.006"/>
      <inertia ixx="0.0000001" ixy="0" ixz="0" iyy="0.0000001" iyz="0" izz="0.0000001"/>
    </inertial>
  </link>
  <joint name="left_middle_coxa_joint" type="revolute">
    <origin rpy="0.0 0.0 1.5707963267948966" xyz="0.0 0.0 0.0"/>
    <parent link="left_middle_leg_base"/>
    <child link="left_middle_coxa"/>
    <axis xyz="0.0 0.0 1.0"/>
    <limit effort="1000.0" lower="-3.141592653589793" upper="3.141592653589793" velocity="1"/>
  </joint>
  <!-- femur -->
  <link name="left_middle_femur">
    <visual>
      <geometry>
        <mesh filename="package://hexapod_urdf/meshes/hopper_leg_femur.stl" scale="0.001 0.001 0.001"/>
      </geometry>
      <material name="white"/>
    </visual>
    <collision>
      <geometry>
        <box size="0.038 0.05 0.032"/>
      </geometry>
      <origin rpy="0 0 0.06981317007977318" xyz="0.00094 -0.01346 0"/>
    </collision>
    <inertial>
      <origin rpy="0 0 0.06981317007977318" xyz="0.00094 -0.01346 0"/>
      <mass value="0.091"/>
      <inertia ixx="0.00002672366667" ixy="0" ixz="0" iyy="0.00001989866667" iyz="0" izz="0.00003109166667"/>
    </inertial>
  </link>
  <joint name="left_middle_femur_joint" type="revolute">
    <origin rpy="-1.5707963267948966 1.5707963267948966 0.0" xyz="0.044 0.0 0.0"/>
    <parent link="left_middle_coxa"/>
    <child link="left_middle_femur"/>
    <axis xyz="0.0 0.0 1"/>
    <limit effort="1000.0" lower="-3.141592653589793" upper="3.141592653589793" velocity="1"/>
  </joint>
  <!-- tibia -->
  <link name="left_middle_tibia">
    <visual>
      <geometry>
        <mesh filename="package://hexapod_urdf/meshes/hopper_leg_tibia.stl" scale="0.001 0.001 0.001"/>
      </geometry>
      <material name="white"/>
    </visual>
    <collision>
      <geometry>
        <box size="0.124 0.019 0.04"/>
      </geometry>
      <origin rpy="0 0 -0.29671256645162386" xyz="0.0535 0.023 0"/>
    </collision>
    <inertial>
      <origin rpy="0 0 -0.29671256645162386" xyz="0.0535 0.023 0"/>
      <mass value="0.091"/>
      <inertia ixx="0.0000148709166667" ixy="0" ixz="0" iyy="0.00016938133333" iyz="0" izz="0.0001599855833333"/>
    </inertial>
  </link>
  <joint name="left_middle_tibia_joint" type="revolute">
    <origin rpy="3.141592653589793 0.0 0.0" xyz="0.0 -0.07 0.0"/>
    <parent link="left_middle_femur"/>
    <child link="left_middle_tibia"/>
    <axis xyz="0.0 0.0 -1"/>
    <limit effort="1000.0" lower="-3.141592653589793" upper="3.141592653589793" velocity="1"/>
  </joint>
  <link name="left_middle_button">
    <inertial>
      <origin rpy="0 0 0" xyz="0 0 0"/>
      <mass value="0.006"/>
      <inertia ixx="0.0000001" ixy="0" ixz="0" iyy="0.0000001" iyz="0" izz="0.0000001"/>
    </inertial>
  </link>
  <joint name="left_middle_tibia_button" type="fixed">
    <origin xyz="0.128 0.0 0.0"/>
    <parent link="left_middle_tibia"/>
    <child link="left_middle_button"/>
  </joint>
  <!-- leg base -->
  <link name="left_front_leg_base">
    <inertial>
      <origin rpy="0 0 0" xyz="0 0 0"/>
      <mass value="0.006"/>
      <inertia ixx="0.0000001" ixy="0" ixz="0" iyy="0.0000001" iyz="0" izz="0.0000001"/>
    </inertial>
  </link>
  <joint name="left_front_leg_base_joint" type="fixed">
    <origin rpy="0.0 0.0 0.0" xyz="0.065 0.0325 0.0"/>
    <parent link="body_link"/>
    <child link="left_front_leg_base"/>
  </joint>
  <!-- coxa -->
  <link name="left_front_coxa">
    <visual>
      <geometry>
        <mesh filename="package://hexapod_urdf/meshes/hopper_leg_coxa.stl" scale="0.001 0.001 0.001"/>
      </geometry>
      <material name="white"/>
    </visual>
    <inertial>
      <origin rpy="0 0 0" xyz="0 0 0"/>
      <mass value="0.006"/>
      <inertia ixx="0.0000001" ixy="0" ixz="0" iyy="0.0000001" iyz="0" izz="0.0000001"/>
    </inertial>
  </link>
  <joint name="left_front_coxa_joint" type="revolute">
    <origin rpy="0.0 0.0 1.5707963267948966" xyz="0.0 0.0 0.0"/>
    <parent link="left_front_leg_base"/>
    <child link="left_front_coxa"/>
    <axis xyz="0.0 0.0 1.0"/>
    <limit effort="1000.0" lower="-3.141592653589793" upper="3.141592653589793" velocity="1"/>
  </joint>
  <!-- femur -->
  <link name="left_front_femur">
    <visual>
      <geometry>
        <mesh filename="package://hexapod_urdf/meshes/hopper_leg_femur.stl" scale="0.001 0.001 0.001"/>
      </geometry>
      <material name="white"/>
    </visual>
    <collision>
      <geometry>
        <box size="0.038 0.05 0.032"/>
      </geometry>
      <origin rpy="0 0 0.06981317007977318" xyz="0.00094 -0.01346 0"/>
    </collision>
    <inertial>
      <origin rpy="0 0 0.06981317007977318" xyz="0.00094 -0.01346 0"/>
      <mass value="0.091"/>
      <inertia ixx="0.00002672366667" ixy="0" ixz="0" iyy="0.00001989866667" iyz="0" izz="0.00003109166667"/>
    </inertial>
  </link>
  <joint name="left_front_femur_joint" type="revolute">
    <origin rpy="-1.5707963267948966 1.5707963267948966 0.0" xyz="0.044 0.0 0.0"/>
    <parent link="left_front_coxa"/>
    <child link="left_front_femur"/>
    <axis xyz="0.0 0.0 1"/>
    <limit effort="1000.0" lower="-3.141592653589793" upper="3.141592653589793" velocity="1"/>
  </joint>
  <!-- tibia -->
  <link name="left_front_tibia">
    <visual>
      <geometry>
        <mesh filename="package://hexapod_urdf/meshes/hopper_leg_tibia.stl" scale="0.001 0.001 0.001"/>
      </geometry>
      <material name="white"/>
    </visual>
    <collision>
      <geometry>
        <box size="0.124 0.019 0.04"/>
      </geometry>
      <origin rpy="0 0 -0.29671256645162386" xyz="0.0535 0.023 0"/>
    </collision>
    <inertial>
      <origin rpy="0 0 -0.29671256645162386" xyz="0.0535 0.023 0"/>
      <mass value="0.091"/>
      <inertia ixx="0.0000148709166667" ixy="0" ixz="0" iyy="0.00016938133333" iyz="0" izz="0.0001599855833333"/>
    </inertial>
  </link>
  <joint name="left_front_tibia_joint" type="revolute">
    <origin rpy="3.141592653589793 0.0 0.0" xyz="0.0 -0.07 0.0"/>
    <parent link="left_front_femur"/>
    <child link="left_front_tibia"/>
    <axis xyz="0.0 0.0 -1"/>
    <limit effort="1000.0" lower="-3.141592653589793" upper="3.141592653589793" velocity="1"/>
  </joint>
  <link name="left_front_button">
    <inertial>
      <origin rpy="0 0 0" xyz="0 0 0"/>
      <mass value="0.006"/>
      <inertia ixx="0.0000001" ixy="0" ixz="0" iyy="0.0000001" iyz="0" izz="0.0000001"/>
    </inertial>
  </link>
  <joint name="left_front_tibia_button" type="fixed">
    <origin xyz="0.128 0.0 0.0"/>
    <parent link="left_front_tibia"/>
    <child link="left_front_button"/>
  </joint>
</robot>
