<?xml version="1.0" encoding="UTF-8" ?>

<robot xmlns:xacro="http://ros.org/wiki/xacro" name="reignblaze">

	<xacro:include filename="accessories/reignblaze_accessories.xacro" />

	<!-- parameters -->
	<xacro:property name="pi" value="3.1415926535897931" />
	<xacro:property name="body_length_x" value="0.27" />
	<xacro:property name="body_length_y" value="0.09" />
	<xacro:property name="coxa_length" value="0.044" />
	<xacro:property name="femur_length" value="0.0545" />
	<xacro:property name="tibia_length" value="0.1019" />

	<gazebo>
		<plugin name="gazebo_ros_control" filename="libgazebo_ros_control.so">
			<robotNamespace>/reignblaze</robotNamespace>
		</plugin>
	</gazebo>

	<link name="base_footprint"/>

	<joint name="base_joint" type="fixed">
		<parent link="base_footprint"/>
		<child link="base_link"/>
		<origin xyz="0 0 0" rpy="0 0 0"/>
	</joint>

	<link name="base_link"/>

	<joint name="body_joint" type="fixed">
		<parent link="base_link" />
		<child link="body_link" />
		<origin xyz="0.0 0.0 0.0" rpy="0.0 0.0 0.0" />
	</joint>

	<link name="body_link">
		<visual>
	  		<origin xyz="0.0 0.0 0.0" rpy="${pi/2} 0.0 0.0" />
			<geometry>
				<mesh filename="package://hexapod_description/meshes/reignblaze/body.stl" scale="0.001 0.001 0.001"/>
			</geometry>
			<material name="white">
				<color rgba="1.0 1.0 1.0 1.0"/>
			</material>
		</visual>
		<collision>
			<origin xyz="0.0 0.0 0.04225" rpy="0.0 0.0 0.0"/>
			<geometry>
				<box size="${body_length_x} ${body_length_y} 0.121" />
			</geometry>
			<material name="acrylic">
				<color rgba="0.9 0.9 1.0 0.6"/>
			</material>
		</collision>
		<inertial>
			<origin xyz="0.0 0.0 0.0" rpy="0.0 0.0 0.0" />
			<mass value="0.84"/>
			<inertia
			ixx="0.001592" ixy="0.0"  ixz="0.0"
			iyy="0.006128" iyz="0.0"
			izz="0.005670" />
		</inertial>
	</link>

	<gazebo reference="body_link">
		<material>Gazebo/White</material>
	</gazebo>

	<!-- Joint properties -->
	<xacro:property name="joint_lower_limit" value="-${pi}" />
	<xacro:property name="joint_upper_limit" value="${pi}" />
	<xacro:property name="joint_effort" value="6.0" />
	<xacro:property name="joint_velocity" value="0.524" />
	<!--
	<xacro:property name="joint_lower_limit" value="-2.6179939" />
	<xacro:property name="joint_upper_limit" value="2.6179939" />
	<xacro:property name="joint_effort" value="2.8" />
	<xacro:property name="joint_velocity" value="5.6548668" />
	-->

	<!-- Leg macro -->
	<xacro:macro name="leg" params="side position x y angle axis">

		<!-- leg position -->
		<!--
		<joint name="leg_center_joint_${side}${position}" type="fixed">
			<origin xyz="${x} ${y} 0.0" rpy="0.0 0.0 0.0" />
			<parent link="body_link" />
			<child link="leg_center_${side}${position}" />
		</joint>

		<link name="leg_center_${side}${position}" >
			<inertial>
				<origin xyz="0.0 0.0 0.0" rpy="0.0 0.0 0.0" />
				<mass value="0.000001"/>
				<inertia
					ixx="0.0" ixy="0.0" ixz="0.0"
					iyy="0.0" iyz="0.0"
					izz="0.0"/>
			</inertial>
			
		</link>
		-->

		<!-- coxa -->
		<joint name="coxa_joint_${side}${position}" type="revolute">
			<origin xyz="${x} ${y} 0.0" rpy="0.0 0.0 ${angle}" />
			<parent link="body_link" />
			<child link="coxa_${side}${position}" />
			<axis xyz="0.0 0.0 1.0" />
			<limit lower="${joint_lower_limit}" upper="${joint_upper_limit}" effort="${joint_effort}" velocity="${joint_velocity}" />
		</joint>
		<transmission name="coxa_transmission_${side}${position}">
			<type>transmission_interface/SimpleTransmission</type>
			<joint name="coxa_joint_${side}${position}">
				<hardwareInterface>hardware_interface/EffortJointInterface</hardwareInterface>
			</joint>
			<actuator name="coxa_motor_${side}${position}">
				<hardwareInterface>hardware_interface/EffortJointInterface</hardwareInterface>
				<mechanicalReduction>1</mechanicalReduction>
			</actuator>
		</transmission>
		<link name="coxa_${side}${position}">
			<visual>
				<origin xyz="0.0 0.0 0.0" rpy="0.0 0.0 ${pi/2}"/>
				<geometry>
					<mesh filename="package://hexapod_description/meshes/reignblaze/coxa.stl" scale="0.001 0.001 0.001"/>
				</geometry>
				<material name="black">
					<color rgba="0.0 0.0 0.0 1.0"/>
				</material>
			</visual>
			<!--
			<collision>
				<origin xyz="-0.00225 0.0 0.0" rpy="0.0 0.0 0.0" />
				<geometry>
					<box size="0.0275 0.032 0.040"/>
				</geometry>
				<material name="acrylic">
					<color rgba="0.9 0.9 1.0 0.6"/>
				</material>
			</collision>
			-->
			<inertial>
				<origin xyz="-0.00225 0.0 0.0" rpy="0.0 0.0 0.0" />
				<mass value="0.056"/>
				<inertia
				ixx="0.000012245" ixy="0.0"  ixz="0.0"
				iyy="0.000010996" iyz="0.0"
				izz="0.000008308" />
		    </inertial>
		</link>
		<gazebo reference="coxa_${side}${position}">
			<material>Gazebo/Black</material>
		</gazebo>

		<!-- femur -->
		<joint name="femur_joint_${side}${position}" type="revolute">
			<origin xyz="${coxa_length} 0.0 0.0" rpy="-${pi/2} ${pi/2} 0.0" />
			<parent link="coxa_${side}${position}" />
			<child link="femur_${side}${position}" />
			<axis xyz="0.0 0.0 ${-axis}" />
			<limit lower="${joint_lower_limit}" upper="${joint_upper_limit}" effort="${joint_effort}" velocity="${joint_velocity}" />
		</joint>
		<transmission name="femur_transmission_${side}${position}">
			<type>transmission_interface/SimpleTransmission</type>
			<joint name="femur_joint_${side}${position}">
				<hardwareInterface>hardware_interface/EffortJointInterface</hardwareInterface>
			</joint>
			<actuator name="femur_motor_${side}${position}">
				<hardwareInterface>hardware_interface/EffortJointInterface</hardwareInterface>
				<mechanicalReduction>1</mechanicalReduction>
			</actuator>
		</transmission>
		<link name="femur_${side}${position}">
			<visual>
				<origin xyz="0.0 0.0 0.0" rpy="0.0 -${pi/2} ${pi/2}"/>
				<geometry>
					<mesh filename="package://hexapod_description/meshes/reignblaze/femur.stl" scale="0.001 0.001 0.001"/>
				</geometry>
				<material name="dark">
					<color rgba="0.3 0.3 0.3 1.0"/>
				</material>
			</visual>
		    	<collision>
				<origin xyz="0.0 -0.0135 0.0" rpy="0.0 0.0 0.0" />
				<geometry>
					<box size="0.032 0.050 0.040"/>
				</geometry>
				<material name="acrylic">
					<color rgba="0.9 0.9 1.0 0.6"/>
				</material>
			</collision>
			<collision>
				<origin xyz="-0.0135 -0.0545 0.0" rpy="0.0 0.0 0.0" />
				<geometry>
					<box size="0.050 0.032 0.040"/>
				</geometry>
				<material name="acrylic">
					<color rgba="0.9 0.9 1.0 0.6"/>
				</material>
			</collision>
			<inertial>
				<origin xyz="0.0 -0.0135 0.0" rpy="0.0 0.0 0.0" />
				<mass value="0.056"/>
				<inertia
				ixx="0.000019133" ixy="0.0"  ixz="0.0"
				iyy="0.000012245" iyz="0.0"
				izz="0.000016445" />
			</inertial>
			<inertial>
				<origin xyz="-0.0135 -0.0545 0.0" rpy="0.0 0.0 0.0" />
				<mass value="0.056"/>
				<inertia
				ixx="0.000012245" ixy="0.0"  ixz="0.0"
				iyy="0.000019133" iyz="0.0"
				izz="0.000016445" />
			</inertial>
		</link>
		<gazebo reference="femur_${side}${position}">
			<material>Gazebo/DarkGrey</material>
		</gazebo>

		<!-- tibia -->
		<joint name="tibia_joint_${side}${position}" type="revolute">
			<origin xyz="0.0 -${femur_length} 0.0" rpy="${pi} 0.0 0.0" />
			<parent link="femur_${side}${position}" />
			<child link="tibia_${side}${position}" />
			<axis xyz="0.0 0.0 ${-axis}" />
			<limit lower="${joint_lower_limit}" upper="${joint_upper_limit}" effort="${joint_effort}" velocity="${joint_velocity}" />
		</joint>
		<transmission name="tibia_transmission_${side}${position}">
			<type>transmission_interface/SimpleTransmission</type>
			<joint name="tibia_joint_${side}${position}">
				<hardwareInterface>hardware_interface/EffortJointInterface</hardwareInterface>
			</joint>
			<actuator name="tibia_motor_${side}${position}">
				<hardwareInterface>hardware_interface/EffortJointInterface</hardwareInterface>
				<mechanicalReduction>1</mechanicalReduction>
			</actuator>
		</transmission>
		<link name="tibia_${side}${position}">
			<visual>
				<origin xyz="0.0 0.0 0.0" rpy="0.0 ${pi/2} ${pi/2}"/>
				<geometry>
					<mesh filename="package://hexapod_description/meshes/reignblaze/tibia.stl" scale="0.001 0.001 0.001"/>
				</geometry>
				<material name="black">
					<color rgba="0.0 0.0 0.0 1.0"/>
				</material>
			</visual>
			<collision>
				<origin xyz="0.0516 0.0 0.0" rpy="0.0 0.0 0.0" />
				<geometry>
					<box size="0.065 0.01 0.0475"/>
				</geometry>
				<material name="acrylic">
					<color rgba="0.9 0.9 1.0 0.6"/>
				</material>
			</collision>
			<collision>
				<origin xyz="0.0967 0.0 0.0" rpy="0.0 ${pi/2} 0.0" />
				<geometry>
					<sphere radius="0.0071"/>
				</geometry>
				<material name="acrylic">
					<color rgba="0.9 0.9 1.0 0.6"/>
				</material>
			</collision>
			<inertial>
				<origin xyz="0.0516 0.0 0.0" rpy="0.0 0.0 0.0" />
				<mass value="0.014"/>
				<inertia
				ixx="0.000002749" ixy="0.0"  ixz="0.0"
				iyy="0.000007561" iyz="0.0"
				izz="0.000005046" />
			</inertial>
		</link>
		<gazebo reference="tibia_${side}${position}">
			<material>Gazebo/Black</material>
		</gazebo>

	</xacro:macro>

<!-- Build robot model -->
	<xacro:leg side="R" position="R" x="-0.065" y="-0.0325" angle="-${116.25*pi/180}" axis="1" />
	<xacro:leg side="R" position="M" x="0.0" y="-0.0625" angle="-${pi/2}" axis="1" />
	<xacro:leg side="R" position="F" x="0.065" y="-0.0325" angle="-${63.75*pi/180}" axis="1" />

	<xacro:leg side="L" position="R" x="-0.065" y="0.0325" angle="${116.25*pi/180}" axis="-1" />
	<xacro:leg side="L" position="M" x="0.0" y="0.0625" angle="${pi/2}" axis="-1" />
	<xacro:leg side="L" position="F" x="0.065" y="0.0325" angle="${63.75*pi/180}" axis="-1" />

</robot>
